<?xml version="1.0" ?>
<!-- =================================================================================== -->
<!-- |    This document was autogenerated by xacro from xarm_device.urdf.xacro         | -->
<!-- |    EDITING THIS FILE BY HAND IS NOT RECOMMENDED                                 | -->
<!-- =================================================================================== -->
<robot name="UF_ROBOT">
  <!-- Insert at the beginning of xarm_device_macro.xacro -->
  <material name="Black">
    <color rgba="0.0 0.0 0.0 1.0"/>
  </material>
  <material name="Red">
    <color rgba="0.8 0.0 0.0 1.0"/>
  </material>
  <material name="White">
    <color rgba="1.0 1.0 1.0 1.0"/>
  </material>
  <material name="Silver">
    <color rgba="0.753 0.753 0.753 1.0"/>
  </material>
  <link name="world"/>
  <joint name="world_joint" type="fixed">
    <parent link="world"/>
    <child link="link_base"/>
    <origin rpy="0 0 0" xyz="0 0 0"/>
  </joint>
  <ros2_control name="uf_robot_hardware/UFRobotSystemHardware" type="system">
    <hardware>
      <plugin>uf_robot_hardware/UFRobotSystemHardware</plugin>
      <param name="hw_ns">xarm</param>
      <param name="velocity_control">False</param>
      <param name="prefix">P</param>
      <param name="robot_ip">R</param>
      <param name="report_type">normal</param>
      <param name="dof">7</param>
      <param name="baud_checkset">True</param>
      <param name="default_gripper_baud">2000000</param>
      <param name="robot_type">xarm</param>
      <param name="add_gripper">False</param>
      <param name="add_bio_gripper">False</param>
    </hardware>
    <joint name="joint1">
      <command_interface name="position">
        <param name="min">-6.283185307179586</param>
        <param name="max">6.283185307179586</param>
      </command_interface>
      <command_interface name="velocity">
        <param name="min">-3.14</param>
        <param name="max">3.14</param>
      </command_interface>
      <state_interface name="position"/>
      <state_interface name="velocity"/>
      <!-- <state_interface name="effort"/> -->
    </joint>
    <joint name="joint2">
      <command_interface name="position">
        <param name="min">-2.059</param>
        <param name="max">2.0944</param>
      </command_interface>
      <command_interface name="velocity">
        <param name="min">-3.14</param>
        <param name="max">3.14</param>
      </command_interface>
      <state_interface name="position"/>
      <state_interface name="velocity"/>
      <!-- <state_interface name="effort"/> -->
    </joint>
    <joint name="joint3">
      <command_interface name="position">
        <param name="min">-6.283185307179586</param>
        <param name="max">6.283185307179586</param>
      </command_interface>
      <command_interface name="velocity">
        <param name="min">-3.14</param>
        <param name="max">3.14</param>
      </command_interface>
      <state_interface name="position"/>
      <state_interface name="velocity"/>
      <!-- <state_interface name="effort"/> -->
    </joint>
    <joint name="joint4">
      <command_interface name="position">
        <param name="min">-0.19198</param>
        <param name="max">3.927</param>
      </command_interface>
      <command_interface name="velocity">
        <param name="min">-3.14</param>
        <param name="max">3.14</param>
      </command_interface>
      <state_interface name="position"/>
      <state_interface name="velocity"/>
      <!-- <state_interface name="effort"/> -->
    </joint>
    <joint name="joint5">
      <command_interface name="position">
        <param name="min">-6.283185307179586</param>
        <param name="max">6.283185307179586</param>
      </command_interface>
      <command_interface name="velocity">
        <param name="min">-3.14</param>
        <param name="max">3.14</param>
      </command_interface>
      <state_interface name="position"/>
      <state_interface name="velocity"/>
      <!-- <state_interface name="effort"/> -->
    </joint>
    <joint name="joint6">
      <command_interface name="position">
        <param name="min">-1.69297</param>
        <param name="max">3.141592653589793</param>
      </command_interface>
      <command_interface name="velocity">
        <param name="min">-3.14</param>
        <param name="max">3.14</param>
      </command_interface>
      <state_interface name="position"/>
      <state_interface name="velocity"/>
      <!-- <state_interface name="effort"/> -->
    </joint>
    <joint name="joint7">
      <command_interface name="position">
        <param name="min">-6.283185307179586</param>
        <param name="max">6.283185307179586</param>
      </command_interface>
      <command_interface name="velocity">
        <param name="min">-3.14</param>
        <param name="max">3.14</param>
      </command_interface>
      <state_interface name="position"/>
      <state_interface name="velocity"/>
      <!-- <state_interface name="effort"/> -->
    </joint>
  </ros2_control>
  <link name="link_base">
    <inertial>
      <origin rpy="0 0 0" xyz="-0.00027569 -0.00002500 0.07259089"/>
      <mass value="1.875"/>
      <inertia ixx="0.00484966" ixy="0.00000285" ixz="0.00002471" iyy="0.00487983" iyz="0.00000243" izz="0.00231210"/>
    </inertial>
    <visual>
      <geometry>
        <mesh filename="xarm7_1305/visual/link_base.dae"/>
      </geometry>
      <origin rpy="0 0 0" xyz="0 0 0"/>
      <material name="White"/>
    </visual>
    <collision>
      <geometry>
        <mesh filename="xarm7_1305/collision/link_base.stl"/>
      </geometry>
      <origin rpy="0 0 0" xyz="0 0 0"/>
    </collision>
  </link>
  <link name="link1">
    <inertial>
      <origin rpy="0 0 0" xyz="-0.00000001 0.00160599 -0.03216111"/>
      <mass value="2.168"/>
      <inertia ixx="0.00626097" ixy="0.0" ixz="-0.00000112" iyy="0.00573739" iyz="0.00031090" izz="0.00308031"/>
    </inertial>
    <visual>
      <geometry>
        <mesh filename="xarm7_1305/visual/link1.dae"/>
      </geometry>
      <origin rpy="0 0 0" xyz="0 0 0"/>
      <material name="White"/>
    </visual>
    <collision>
      <geometry>
        <mesh filename="xarm7_1305/collision/link1.stl"/>
      </geometry>
      <origin rpy="0 0 0" xyz="0 0 0"/>
    </collision>
  </link>
  <joint name="joint1" type="revolute">
    <origin rpy="0 0 0" xyz="0 0 0.267"/>
    <parent link="link_base"/>
    <child link="link1"/>
    <axis xyz="0 0 1"/>
    <limit effort="50" lower="-6.283185307179586" upper="6.283185307179586" velocity="3.14"/>
    <dynamics damping="10" friction="1"/>
  </joint>
  <link name="link2">
    <inertial>
      <origin rpy="0 0 0" xyz="0.00000447 -0.08442622 0.04721398"/>
      <mass value="2.73"/>
      <inertia ixx="0.01465324" ixy="-0.00000021" ixz="0.00000103" iyy="0.00694666" iyz="0.00443101" izz="0.01056342"/>
    </inertial>
    <visual>
      <geometry>
        <mesh filename="xarm7_1305/visual/link2.dae"/>
      </geometry>
      <origin rpy="0 0 0" xyz="0 0 0"/>
      <material name="White"/>
    </visual>
    <collision>
      <geometry>
        <mesh filename="xarm7_1305/collision/link2.stl"/>
      </geometry>
      <origin rpy="0 0 0" xyz="0 0 0"/>
    </collision>
  </link>
  <joint name="joint2" type="revolute">
    <origin rpy="-1.5708 0 0" xyz="0 0 0"/>
    <parent link="link1"/>
    <child link="link2"/>
    <axis xyz="0 0 1"/>
    <limit effort="50" lower="-2.059" upper="2.0944" velocity="3.14"/>
    <dynamics damping="10" friction="1"/>
  </joint>
  <link name="link3">
    <inertial>
      <origin rpy="0 0 0" xyz="0.02906440 0.00556162 -0.03120185"/>
      <mass value="1.923"/>
      <inertia ixx="0.00459931" ixy="-0.00001085" ixz="0.00161543" iyy="0.00532435" iyz="0.00013063" izz="0.00352704"/>
    </inertial>
    <visual>
      <geometry>
        <mesh filename="xarm7_1305/visual/link3.dae"/>
      </geometry>
      <origin rpy="0 0 0" xyz="0 0 0"/>
      <material name="White"/>
    </visual>
    <collision>
      <geometry>
        <mesh filename="xarm7_1305/collision/link3.stl"/>
      </geometry>
      <origin rpy="0 0 0" xyz="0 0 0"/>
    </collision>
  </link>
  <joint name="joint3" type="revolute">
    <origin rpy="1.5708 0 0" xyz="0 -0.293 0"/>
    <parent link="link2"/>
    <child link="link3"/>
    <axis xyz="0 0 1"/>
    <limit effort="30" lower="-6.283185307179586" upper="6.283185307179586" velocity="3.14"/>
    <dynamics damping="5" friction="1"/>
  </joint>
  <link name="link4">
    <inertial>
      <origin rpy="0 0 0" xyz="0.05708279 -0.07189834 0.04205398"/>
      <mass value="2.577"/>
      <inertia ixx="0.01083792" ixy="-0.00335663" ixz="-0.00183695" iyy="0.00826380" iyz="0.00318387" izz="0.01036678"/>
    </inertial>
    <visual>
      <geometry>
        <mesh filename="xarm7_1305/visual/link4.dae"/>
      </geometry>
      <origin rpy="0 0 0" xyz="0 0 0"/>
      <material name="White"/>
    </visual>
    <collision>
      <geometry>
        <mesh filename="xarm7_1305/collision/link4.stl"/>
      </geometry>
      <origin rpy="0 0 0" xyz="0 0 0"/>
    </collision>
  </link>
  <joint name="joint4" type="revolute">
    <origin rpy="1.5708 0 0" xyz="0.0525 0 0"/>
    <parent link="link3"/>
    <child link="link4"/>
    <axis xyz="0 0 1"/>
    <limit effort="30" lower="-0.19198" upper="3.927" velocity="3.14"/>
    <dynamics damping="5" friction="1"/>
  </joint>
  <link name="link5">
    <inertial>
      <origin rpy="0 0 0" xyz="0.00016816 0.03090249 -0.08031427"/>
      <mass value="1.413"/>
      <inertia ixx="0.00844774" ixy="0.0" ixz="0.00000002" iyy="0.00761972" iyz="0.00195119" izz="0.00199753"/>
    </inertial>
    <visual>
      <geometry>
        <mesh filename="xarm7_1305/visual/link5.dae"/>
      </geometry>
      <origin rpy="0 0 0" xyz="0 0 0"/>
      <material name="White"/>
    </visual>
    <collision>
      <geometry>
        <mesh filename="xarm7_1305/collision/link5.stl"/>
      </geometry>
      <origin rpy="0 0 0" xyz="0 0 0"/>
    </collision>
  </link>
  <joint name="joint5" type="revolute">
    <origin rpy="1.5708 0 0" xyz="0.0775 -0.3425 0"/>
    <parent link="link4"/>
    <child link="link5"/>
    <axis xyz="0 0 1"/>
    <limit effort="30" lower="-6.283185307179586" upper="6.283185307179586" velocity="3.14"/>
    <dynamics damping="5" friction="1"/>
  </joint>
  <link name="link6">
    <inertial>
      <origin rpy="0 0 0" xyz="0.04616698 0.00947581 0.00846414"/>
      <mass value="1.388"/>
      <inertia ixx="0.00159996" ixy="0.00038970" ixz="-0.00046448" iyy="0.00295668" iyz="-0.00011078" izz="0.00327270"/>
    </inertial>
    <visual>
      <geometry>
        <mesh filename="xarm7_1305/visual/link6.dae"/>
      </geometry>
      <origin rpy="0 0 0" xyz="0 0 0"/>
      <material name="White"/>
    </visual>
    <collision>
      <geometry>
        <mesh filename="xarm7_1305/collision/link6.stl"/>
      </geometry>
      <origin rpy="0 0 0" xyz="0 0 0"/>
    </collision>
  </link>
  <joint name="joint6" type="revolute">
    <origin rpy="1.5708 0 0" xyz="0 0 0"/>
    <parent link="link5"/>
    <child link="link6"/>
    <axis xyz="0 0 1"/>
    <limit effort="20" lower="-1.69297" upper="3.141592653589793" velocity="3.14"/>
    <dynamics damping="2" friction="1"/>
  </joint>
  <link name="link7">
    <inertial>
      <origin rpy="0 0 0" xyz="0.00006906 -0.00179820 -0.01774746"/>
      <mass value="0.223"/>
      <inertia ixx="0.00011692" ixy="0.0" ixz="0.0" iyy="0.00009809" iyz="0.00000049" izz="0.00018277"/>
    </inertial>
    <visual>
      <geometry>
        <mesh filename="xarm7_1305/visual/link7.dae"/>
      </geometry>
      <origin rpy="0 0 0" xyz="0 0 0"/>
      <material name="Silver"/>
    </visual>
    <collision>
      <geometry>
        <mesh filename="xarm7_1305/collision/link7.stl"/>
      </geometry>
      <origin rpy="0 0 0" xyz="0 0 0"/>
    </collision>
  </link>
  <joint name="joint7" type="revolute">
    <origin rpy="-1.5708 0 0" xyz="0.076 0.097 0"/>
    <parent link="link6"/>
    <child link="link7"/>
    <axis xyz="0 0 1"/>
    <limit effort="20" lower="-6.283185307179586" upper="6.283185307179586" velocity="3.14"/>
    <dynamics damping="2" friction="1"/>
  </joint>

  <link name="link_ft">
    <inertial>
      <origin rpy="0 0 0" xyz="0.00012209 -0.00016199 0.02553208"/>
      <mass value="0.445"/>
      <inertia ixx="2.839e-04" ixy="0.0" ixz="0.0" iyy="2.839e-04" iyz="0.0" izz="3.139e-04"/>
    </inertial>
    <visual>
      <geometry>
        <mesh filename="xarm7_1305/visual/link_ft.dae" scale="0.001 0.001 0.001"/>
      </geometry>
      <origin rpy="0 0 0" xyz="0 0 0"/>
      <material name="White"/>
    </visual>
    <collision>
      <geometry>
        <mesh filename="xarm7_1305/collision/link_ft.stl" scale="0.001 0.001 0.001"/>
      </geometry>
      <origin rpy="0 0 0" xyz="0 0 0"/>
    </collision>
  </link>
  <joint name="joint_ft" type="fixed">
    <origin rpy="0 0 0" xyz="0 0 0"/>
    <parent link="link7"/>
    <child link="link_ft"/>
  </joint>
  <link name="link_EE">
    <inertial>
      <origin rpy="0 0 0" xyz="0.0 0.0 0.03279"/>
      <mass value="0.05"/>
      <inertia ixx="6.524e-5" ixy="0.0" ixz="0.0" iyy="3.365e-5" iyz="0.0" izz="6.563e-5"/>
    </inertial>
    <visual>
      <geometry>
        <mesh filename="end_tool/visual/end_effector.dae" scale="0.001 0.001 0.001"/>
      </geometry>
      <origin rpy="1.5708 0 0" xyz="-0.0375 0.0375 0"/>
      <material name="Silver"/>
    </visual>
    <collision>
      <geometry>
        <mesh filename="end_tool/collision/end_effector.stl" scale="0.001 0.001 0.001"/>
      </geometry>
      <origin rpy="1.5708 0 0" xyz="-0.0375 0.0375 0"/>
    </collision>
  </link>

  <joint name="joint_EE" type="fixed">
    <origin rpy="0 0 0" xyz="0 0 0.05860"/>
    <parent link="link_ft"/>
    <child link="link_EE"/>
  </joint>
  
  <link name="link_eef"/>

  <joint name="joint_eef" type="fixed">
    <origin rpy="0 0 0" xyz="0 0 0.0475"/>
    <parent link="link_EE"/>
    <child link="link_eef"/>
  </joint>
</robot>
